<?xml version="1.0" encoding="utf-8"?>
<!-- This URDF was automatically created by SolidWorks to URDF Exporter! Originally created by Stephen Brawner (brawner@gmail.com) 
     Commit Version: 1.5.1-0-g916b5db  Build Version: 1.5.7152.31018
     For more information, please see http://wiki.ros.org/sw_urdf_exporter -->
<robot
  name="05147">
  <link
    name="Base">
    <inertial>
      <origin
        xyz="0.307939482852255 0.0328657288246075 -0.0284063356583994"
        rpy="0 0 0" />
      <mass
        value="5.32485368404392" />
      <inertia
        ixx="0.0149047739356473"
        ixy="1.47975231732829E-06"
        ixz="7.80337094206553E-06"
        iyy="0.0219378727246539"
        iyz="-4.0175158993363E-06"
        izz="0.0232030208257597" />
    </inertial>
    <visual>
      <origin
        xyz="0 0 0"
        rpy="0 0 0" />
      <geometry>
        <mesh
          filename="package://05147/meshes/Base.STL" />
      </geometry>
      <material
        name="">
        <color
          rgba="0.752941176470588 0.752941176470588 0.752941176470588 1" />
      </material>
    </visual>
    <collision>
      <origin
        xyz="0 0 0"
        rpy="0 0 0" />
      <geometry>
        <mesh
          filename="package://05147/meshes/Base.STL" />
      </geometry>
    </collision>
  </link>
  <link
    name="LFS">
    <inertial>
      <origin
        xyz="0.0666875210853829 -0.0254641293387147 0.0267759026382747"
        rpy="0 0 0" />
      <mass
        value="0.26437001106022" />
      <inertia
        ixx="3.20746276473044E-05"
        ixy="-1.44118283518155E-07"
        ixz="-6.3085308435424E-08"
        iyy="6.22704126338821E-05"
        iyz="-2.01894652761256E-07"
        izz="6.28519936953906E-05" />
    </inertial>
    <visual>
      <origin
        xyz="0 0 0"
        rpy="0 0 0" />
      <geometry>
        <mesh
          filename="package://05147/meshes/LFS.STL" />
      </geometry>
      <material
        name="">
        <color
          rgba="0.752941176470588 0.752941176470588 0.752941176470588 1" />
      </material>
    </visual>
    <collision>
      <origin
        xyz="0 0 0"
        rpy="0 0 0" />
      <geometry>
        <mesh
          filename="package://05147/meshes/LFS.STL" />
      </geometry>
    </collision>
  </link>
  <joint
    name="LFS"
    type="prismatic">
    <origin
      xyz="0.399436570242162 -0.17341012423842 0.00422954428193555"
      rpy="-0.307630277882593 0 1.5707963267949" />
    <parent
      link="Base" />
    <child
      link="LFS" />
    <axis
      xyz="0 0.302801016091279 -0.953053799454201" />
    <limit
      lower="0"
      upper="0"
      effort="0"
      velocity="0" />
  </joint>
  <link
    name="LFW">
    <inertial>
      <origin
        xyz="-0.012315724574073 0 0"
        rpy="0 0 0" />
      <mass
        value="0.193585420779862" />
      <inertia
        ixx="0.000253081141332254"
        ixy="-5.88092833198904E-37"
        ixz="5.1845054750851E-21"
        iyy="0.000136818598566517"
        iyz="7.17557753438369E-37"
        izz="0.000136818598566517" />
    </inertial>
    <visual>
      <origin
        xyz="0 0 0"
        rpy="0 0 0" />
      <geometry>
        <mesh
          filename="package://05147/meshes/LFW.STL" />
      </geometry>
      <material
        name="">
        <color
          rgba="1 1 1 1" />
      </material>
    </visual>
    <collision>
      <origin
        xyz="0 0 0"
        rpy="0 0 0" />
      <geometry>
        <mesh
          filename="package://05147/meshes/LFW.STL" />
      </geometry>
    </collision>
  </link>
  <joint
    name="LFW"
    type="continuous">
    <origin
      xyz="0.000410991135076755 -0.0473256302288177 0.0518267010922029"
      rpy="-1.87071350905913 0 -3.14159265358979" />
    <parent
      link="LFS" />
    <child
      link="LFW" />
    <axis
      xyz="1 0 0" />
    <limit
      effort="3.1"
      velocity="7" />
  </joint>
  <link
    name="RFS">
    <inertial>
      <origin
        xyz="0.0724473276378515 -0.0316254871785929 0.0251584272220134"
        rpy="0 0 0" />
      <mass
        value="0.264370011060221" />
      <inertia
        ixx="3.20746276473045E-05"
        ixy="1.44118283518171E-07"
        ixz="6.30853084354421E-08"
        iyy="6.22704126338823E-05"
        iyz="-2.01894652761264E-07"
        izz="6.28519936953909E-05" />
    </inertial>
    <visual>
      <origin
        xyz="0 0 0"
        rpy="0 0 0" />
      <geometry>
        <mesh
          filename="package://05147/meshes/RFS.STL" />
      </geometry>
      <material
        name="">
        <color
          rgba="0.752941176470588 0.752941176470588 0.752941176470588 1" />
      </material>
    </visual>
    <collision>
      <origin
        xyz="0 0 0"
        rpy="0 0 0" />
      <geometry>
        <mesh
          filename="package://05147/meshes/RFS.STL" />
      </geometry>
    </collision>
  </link>
  <joint
    name="RFS"
    type="prismatic">
    <origin
      xyz="0.43812027832165 0.246671664584202 0.00391412689968431"
      rpy="-0.307630277882593 0 -1.5707963267949" />
    <parent
      link="Base" />
    <child
      link="RFS" />
    <axis
      xyz="0 0.302801016091278 -0.953053799454201" />
    <limit
      lower="0"
      upper="0"
      effort="0"
      velocity="0" />
  </joint>
  <link
    name="RFW">
    <inertial>
      <origin
        xyz="-0.0123157245740731 0 1.38777878078145E-17"
        rpy="0 0 0" />
      <mass
        value="0.193585420779862" />
      <inertia
        ixx="0.000253081141332254"
        ixy="-1.23497249055924E-21"
        ixz="2.07163812308337E-21"
        iyy="0.000136818598566517"
        iyz="-3.3881317890172E-21"
        izz="0.000136818598566517" />
    </inertial>
    <visual>
      <origin
        xyz="0 0 0"
        rpy="0 0 0" />
      <geometry>
        <mesh
          filename="package://05147/meshes/RFW.STL" />
      </geometry>
      <material
        name="">
        <color
          rgba="1 1 1 1" />
      </material>
    </visual>
    <collision>
      <origin
        xyz="0 0 0"
        rpy="0 0 0" />
      <geometry>
        <mesh
          filename="package://05147/meshes/RFW.STL" />
      </geometry>
    </collision>
  </link>
  <joint
    name="RFW"
    type="continuous">
    <origin
      xyz="0.00617079768754525 -0.0282283703997553 0.0582235217032619"
      rpy="-0.707139785690462 0 3.14159265358979" />
    <parent
      link="RFS" />
    <child
      link="RFW" />
    <axis
      xyz="1 0 0" />
    <limit
      effort="3.1"
      velocity="7" />
  </joint>
  <link
    name="LBS">
    <inertial>
      <origin
        xyz="0.0754022136877308 -0.0205417144756382 0.0124394069979403"
        rpy="0 0 0" />
      <mass
        value="0.197009126147877" />
      <inertia
        ixx="1.68802738687173E-05"
        ixy="-1.31305180801582E-21"
        ixz="1.60621727337229E-20"
        iyy="5.0218488566757E-05"
        iyz="1.0508875929185E-06"
        izz="4.72447473350487E-05" />
    </inertial>
    <visual>
      <origin
        xyz="0 0 0"
        rpy="0 0 0" />
      <geometry>
        <mesh
          filename="package://05147/meshes/LBS.STL" />
      </geometry>
      <material
        name="">
        <color
          rgba="0.752941176470588 0.752941176470588 0.752941176470588 1" />
      </material>
    </visual>
    <collision>
      <origin
        xyz="0 0 0"
        rpy="0 0 0" />
      <geometry>
        <mesh
          filename="package://05147/meshes/LBS.STL" />
      </geometry>
    </collision>
  </link>
  <joint
    name="LBS"
    type="prismatic">
    <origin
      xyz="0.219436570242162 -0.17341012423842 0.0125771650360316"
      rpy="-0.307630277882593 0 1.5707963267949" />
    <parent
      link="Base" />
    <child
      link="LBS" />
    <axis
      xyz="0 0.302801016091285 -0.953053799454199" />
    <limit
      lower="0"
      upper="0"
      effort="0"
      velocity="0" />
  </joint>
  <link
    name="LBC">
    <inertial>
      <origin
        xyz="0.000464526735875104 -0.0408268141997156 -2.77555756156289E-17"
        rpy="0 0 0" />
      <mass
        value="0.043396245960262" />
      <inertia
        ixx="2.1180042472488E-05"
        ixy="5.53822046363834E-07"
        ixz="1.7205356741103E-22"
        iyy="1.76453344713605E-06"
        iyz="-2.20642156592395E-20"
        izz="2.14947085785555E-05" />
    </inertial>
    <visual>
      <origin
        xyz="0 0 0"
        rpy="0 0 0" />
      <geometry>
        <mesh
          filename="package://05147/meshes/LBC.STL" />
      </geometry>
      <material
        name="">
        <color
          rgba="0.898039215686275 0.917647058823529 0.929411764705882 1" />
      </material>
    </visual>
    <collision>
      <origin
        xyz="0 0 0"
        rpy="0 0 0" />
      <geometry>
        <mesh
          filename="package://05147/meshes/LBC.STL" />
      </geometry>
    </collision>
  </link>
  <joint
    name="LBC"
    type="continuous">
    <origin
      xyz="0.0411609911350767 -0.0167580647011466 0.000530524260584295"
      rpy="-1.87842355251803 -0.00139263512405277 3.13720937469085" />
    <parent
      link="LBS" />
    <child
      link="LBC" />
    <axis
      xyz="0 1 0" />
  </joint>
  <link
    name="LBW">
    <inertial>
      <origin
        xyz="0.00647268691618069 1.38777878078145E-17 2.77555756156289E-17"
        rpy="0 0 0" />
      <mass
        value="0.0368891747697499" />
      <inertia
        ixx="1.67269024516251E-05"
        ixy="1.7292210705421E-21"
        ixz="-4.76786905075565E-21"
        iyy="8.8792623904253E-06"
        iyz="2.11758236813575E-22"
        izz="8.8792623904253E-06" />
    </inertial>
    <visual>
      <origin
        xyz="0 0 0"
        rpy="0 0 0" />
      <geometry>
        <mesh
          filename="package://05147/meshes/LBW.STL" />
      </geometry>
      <material
        name="">
        <color
          rgba="1 1 1 1" />
      </material>
    </visual>
    <collision>
      <origin
        xyz="0 0 0"
        rpy="0 0 0" />
      <geometry>
        <mesh
          filename="package://05147/meshes/LBW.STL" />
      </geometry>
    </collision>
  </link>
  <joint
    name="LBW"
    type="continuous">
    <origin
      xyz="0.0095006 -0.0683 0"
      rpy="-2.9585 0 0" />
    <parent
      link="LBC" />
    <child
      link="LBW" />
    <axis
      xyz="1 0 0" />
    <limit
      effort="3.1"
      velocity="7" />
  </joint>
  <link
    name="RBS">
    <inertial>
      <origin
        xyz="0.0754022136877308 -0.0205794902065512 0.0125583045641975"
        rpy="0 0 0" />
      <mass
        value="0.197009126147877" />
      <inertia
        ixx="1.68802738687173E-05"
        ixy="-2.46238013369259E-21"
        ixz="6.53536558754259E-22"
        iyy="5.0218488566757E-05"
        iyz="1.0508875929185E-06"
        izz="4.72447473350487E-05" />
    </inertial>
    <visual>
      <origin
        xyz="0 0 0"
        rpy="0 0 0" />
      <geometry>
        <mesh
          filename="package://05147/meshes/RBS.STL" />
      </geometry>
      <material
        name="">
        <color
          rgba="0.752941176470588 0.752941176470588 0.752941176470588 1" />
      </material>
    </visual>
    <collision>
      <origin
        xyz="0 0 0"
        rpy="0 0 0" />
      <geometry>
        <mesh
          filename="package://05147/meshes/RBS.STL" />
      </geometry>
    </collision>
  </link>
  <joint
    name="RBS"
    type="prismatic">
    <origin
      xyz="0.25106 0.24091 0.012452"
      rpy="-0.30763 0 -1.5708" />
    <parent
      link="Base" />
    <child
      link="RBS" />
    <axis
      xyz="0 0.3028 -0.95305" />
    <limit
      lower="0"
      upper="0"
      effort="0"
      velocity="0" />
  </joint>
  <link
    name="RBC">
    <inertial>
      <origin
        xyz="0.000464526735875131 -0.0408268141997156 8.32667268468867E-17"
        rpy="0 0 0" />
      <mass
        value="0.0433962459602619" />
      <inertia
        ixx="2.11800424724879E-05"
        ixy="5.53822046363848E-07"
        ixz="-4.32646056105883E-22"
        iyy="1.76453344713605E-06"
        iyz="2.09764731537322E-20"
        izz="2.14947085785555E-05" />
    </inertial>
    <visual>
      <origin
        xyz="0 0 0"
        rpy="0 0 0" />
      <geometry>
        <mesh
          filename="package://05147/meshes/RBC.STL" />
      </geometry>
      <material
        name="">
        <color
          rgba="0.898039215686275 0.917647058823529 0.929411764705882 1" />
      </material>
    </visual>
    <collision>
      <origin
        xyz="0 0 0"
        rpy="0 0 0" />
      <geometry>
        <mesh
          filename="package://05147/meshes/RBC.STL" />
      </geometry>
    </collision>
  </link>
  <joint
    name="RBC"
    type="continuous">
    <origin
      xyz="0.0411609911350767 -0.0167958404320596 0.000649421826841648"
      rpy="-1.87842660467749 0 3.14159265358979" />
    <parent
      link="RBS" />
    <child
      link="RBC" />
    <axis
      xyz="0 1 0" />
  </joint>
  <link
    name="RBW">
    <inertial>
      <origin
        xyz="0.00647333333471939 -2.77555756156289E-17 1.38777878078145E-17"
        rpy="0 0 0" />
      <mass
        value="0.0368891747697499" />
      <inertia
        ixx="1.67269024516251E-05"
        ixy="-2.22678152353162E-21"
        ixz="-4.57890503447017E-22"
        iyy="8.87926239042531E-06"
        iyz="0"
        izz="8.8792623904253E-06" />
    </inertial>
    <visual>
      <origin
        xyz="0 0 0"
        rpy="0 0 0" />
      <geometry>
        <mesh
          filename="package://05147/meshes/RBW.STL" />
      </geometry>
      <material
        name="">
        <color
          rgba="1 1 1 1" />
      </material>
    </visual>
    <collision>
      <origin
        xyz="0 0 0"
        rpy="0 0 0" />
      <geometry>
        <mesh
          filename="package://05147/meshes/RBW.STL" />
      </geometry>
    </collision>
  </link>
  <joint
    name="RBW"
    type="continuous">
    <origin
      xyz="0.0095 -0.0683 0"
      rpy="0.98365 0 0" />
    <parent
      link="RBC" />
    <child
      link="RBW" />
    <axis
      xyz="1 0 0" />
    <limit
      effort="3.1"
      velocity="7" />
  </joint>
  <link
    name="Lidar">
    <inertial>
      <origin
        xyz="-0.0784930236720806 0.744427434110801 0.133449662205116"
        rpy="0 0 0" />
      <mass
        value="0.0730845741838002" />
      <inertia
        ixx="1.9580876083019E-05"
        ixy="-4.2839116122682E-07"
        ixz="1.03933621130234E-07"
        iyy="4.14184522502777E-05"
        iyz="-9.42743593249038E-09"
        izz="2.41250083307634E-05" />
    </inertial>
    <visual>
      <origin
        xyz="0 0 0"
        rpy="0 0 0" />
      <geometry>
        <mesh
          filename="package://05147/meshes/Lidar.STL" />
      </geometry>
      <material
        name="">
        <color
          rgba="0.792156862745098 0.819607843137255 0.933333333333333 1" />
      </material>
    </visual>
    <collision>
      <origin
        xyz="0 0 0"
        rpy="0 0 0" />
      <geometry>
        <mesh
          filename="package://05147/meshes/Lidar.STL" />
      </geometry>
    </collision>
  </link>
  <joint
    name="Lidar"
    type="fixed">
    <origin
      xyz="0.35169 -0.099167 0.60184"
      rpy="-1.5708 0 0" />
    <parent
      link="Base" />
    <child
      link="Lidar" />
    <axis
      xyz="0 0 0" />
  </joint>
  <link
    name="Front_Cam">
    <inertial>
      <origin
        xyz="0.0498359970771496 0.061783635914709 0.0687226592339399"
        rpy="0 0 0" />
      <mass
        value="0.0436119948521297" />
      <inertia
        ixx="4.2947913749771E-06"
        ixy="-8.85886294505224E-10"
        ixz="-1.01812872210199E-09"
        iyy="2.21058139310684E-05"
        iyz="2.17578140553956E-08"
        izz="2.35707056576044E-05" />
    </inertial>
    <visual>
      <origin
        xyz="0 0 0"
        rpy="0 0 0" />
      <geometry>
        <mesh
          filename="package://05147/meshes/Front_Cam.STL" />
      </geometry>
      <material
        name="">
        <color
          rgba="0.792156862745098 0.819607843137255 0.933333333333333 1" />
      </material>
    </visual>
    <collision>
      <origin
        xyz="0 0 0"
        rpy="0 0 0" />
      <geometry>
        <mesh
          filename="package://05147/meshes/Front_Cam.STL" />
      </geometry>
    </collision>
  </link>
  <joint
    name="Front_Cam"
    type="fixed">
    <origin
      xyz="0.36997 0.08359 -0.039354"
      rpy="-1.5708 0 -1.5708" />
    <parent
      link="Base" />
    <child
      link="Front_Cam" />
    <axis
      xyz="0 0 0" />
  </joint>
  <link
    name="Ball_cam">
    <inertial>
      <origin
        xyz="0.049835996905416 0.061783634979344 0.0687226595626673"
        rpy="0 0 0" />
      <mass
        value="0.0436119951735671" />
      <inertia
        ixx="4.29479052042015E-06"
        ixy="-8.85250524039298E-10"
        ixz="-1.01843894202854E-09"
        iyy="2.21058148306726E-05"
        iyz="2.17581061750883E-08"
        izz="2.35707057120251E-05" />
    </inertial>
    <visual>
      <origin
        xyz="0 0 0"
        rpy="0 0 0" />
      <geometry>
        <mesh
          filename="package://05147/meshes/Ball_cam.STL" />
      </geometry>
      <material
        name="">
        <color
          rgba="0.792156862745098 0.819607843137255 0.933333333333333 1" />
      </material>
    </visual>
    <collision>
      <origin
        xyz="0 0 0"
        rpy="0 0 0" />
      <geometry>
        <mesh
          filename="package://05147/meshes/Ball_cam.STL" />
      </geometry>
    </collision>
  </link>
  <joint
    name="Ball_cam"
    type="fixed">
    <origin
      xyz="0.348557334886622 0.083757378780411 -0.0526888416954217"
      rpy="-0.939475073990972 0 -1.5707963267949" />
    <parent
      link="Base" />
    <child
      link="Ball_cam" />
    <axis
      xyz="0 0 0" />
  </joint>
</robot>